Workbook

Sheet Cover Sheet
B2: Company | C2: Apple Inc.
B3: Ticker | C3: AAPL
B4: Industry | C4: Consumer Electronics
B5: Fiscal Years | C5: FY2023- FY2025
B6: Currency | C6: USD ($millions)
B7: Source | C7: Apple 10-K 2025
B8: Prepared by | C8: Sharayu Patil
B9: Version | C9: v1.0
B10: Last Updated | C10: 28/07/2026

Sheet Check Sheet
B2: Check | C2: FY2025 | D2: FY2024 | E2: FY2023 | F2: Status
B4: Balance Sheet | C4: ='Financial Statements'!D46-'Financial Statements'!D68 -> 0 | D4: ='Financial Statements'!E46-'Financial Statements'!E68 -> 0 | F4: =IF(AND(C4=0,D4=0),"PASS","FAIL") -> PASS
B5: Revenue Totals | C5: ='Financial Statements'!D10-('Financial Statements'!D8+'Financial Statements'!D9) -> 0 | D5: ='Financial Statements'!E10-('Financial Statements'!E8+'Financial Statements'!E9) -> 0 | E5: ='Financial Statements'!F10-('Financial Statements'!F8+'Financial Statements'!F9) -> 0 | F5: =IF(AND(C5=0,D5=0,E5=0),"PASS","FAIL") -> PASS
B6: Cash Flow Statement | C6: ='Financial Statements'!D72+('Financial Statements'!D90+'Financial Statements'!D100+'Financial Statements'!D112)-'Financial Statements'!D116 -> 0 | D6: ='Financial Statements'!E72+('Financial Statements'!E90+'Financial Statements'!E100+'Financial Statements'!E112)-'Financial Statements'!E116 -> 0 | E6: ='Financial Statements'!F72+('Financial Statements'!F90+'Financial Statements'!F100+'Financial Statements'!F112)-'Financial Statements'!F116 -> 0 | F6: =IF(AND(C6=0,D6=0,E6=0),"PASS","FAIL") -> PASS
B7: Common Size Revenue | C7: ='Common Size Statement'!D10-('Common Size Statement'!D9+'Common Size Statement'!D8) -> 0 | D7: ='Common Size Statement'!E10-('Common Size Statement'!E9+'Common Size Statement'!E8) -> 0 | E7: ='Common Size Statement'!F10-('Common Size Statement'!F9+'Common Size Statement'!F8) -> 0 | F7: =IF(AND(C7=0,D7=0,E7=0),"PASS","FAIL") -> PASS

Sheet Assumptions
B2: Item | C2: Value
B4: Reporting Currency | C4: USD ($millions)
B5: Fiscal Year End | C5: September
B6: Years Analysed | C6: FY2023- FY2025
B7: Company | C7: Apple Inc.
B8: Data Source | C8: FY2025 Form 10-K
B9: Share Price Data
B10: Notes | C10: Historical Financial Model

Sheet Financial Statements
B2: Apple Inc. Financial Statements
C4: Units | D4: 46290 | E4: 46289 | F4: 46288
B6: Income Statement
B8: Products | C8: $ | D8: 307003 | E8: 294866 | F8: 298085
B9: Services | C9: $ | D9: 109158 | E9: 96169 | F9: 85200
B10: Total net sales | C10: $ | D10: 416161 | E10: 391035 | F10: 383285
B12: Cost of sales:
B13: Products | C13: $ | D13: 194116 | E13: 185233 | F13: 189282
B14: Services | C14: $ | D14: 26844 | E14: 25119 | F14: 24855
B15: Total cost of sales | C15: $ | D15: 220960 | E15: 210352 | F15: 214137
B16: Gross margin | C16: $ | D16: 195201 | E16: 180683 | F16: 169148
B18: Operating expenses:
B19: Research and development | C19: $ | D19: 34550 | E19: 31370 | F19: 29915
B20: Selling, general and administrative | C20: $ | D20: 27601 | E20: 26097 | F20: 24932
B21: Total operating expenses | C21: $ | D21: 62151 | E21: 57467 | F21: 54847
B23: Operating income | C23: $ | D23: 133050 | E23: 123216 | F23: 114301
B24: Other income/(expense), net | C24: $ | D24: -321 | E24: 269 | F24: -565
B25: Income before provision for income taxes | C25: $ | D25: 132729 | E25: 123485 | F25: 113736
B26: Provision for income taxes | C26: $ | D26: 20719 | E26: 29749 | F26: 16741
B27: Net income | C27: $ | D27: 112010 | E27: 93736 | F27: 96995
B29: Balance Sheet
B31: Current assets:
B32: Cash and cash equivalents | C32: $ | D32: 35934 | E32: 29943
B33: Marketable securities | C33: $ | D33: 18763 | E33: 35228
B34: Accounts receivable, net | C34: $ | D34: 39777 | E34: 33410
B35: Vendor non-trade receivables | C35: $ | D35: 33180 | E35: 32833
B36: Inventories | C36: $ | D36: 5718 | E36: 7286
B37: Other current assets | C37: $ | D37: 14585 | E37: 14287
B38: Total current assets | C38: $ | D38: 147957 | E38: 152987
B40: Non-current assets:
B41: Marketable securities | C41: $ | D41: 77723 | E41: 91479
B42: Property, plant and equipment, net | C42: $ | D42: 49834 | E42: 45680
B43: Other non-current assets | C43: $ | D43: 83727 | E43: 74834
B44: Total non-current assets | C44: $ | D44: 211284 | E44: 211993
B46: Total assets | C46: $ | D46: 359241 | E46: 364980
B48: Current liabilities:
B49: Accounts payable | C49: $ | D49: 69860 | E49: 68960
B50: Other current liabilities | C50: $ | D50: 66387 | E50: 78304
B51: Deferred revenue | C51: $ | D51: 9055 | E51: 8249
B52: Commercial paper | C52: $ | D52: 7979 | E52: 9967
...

Sheet Common Size Statement
B2: Apple Inc.Common Size Statements
C4: Units | D4: 46290 | E4: 46289 | F4: 46288
B6: Income Statement
B8: ='Financial Statements'!B8 -> Products | C8: % | D8: ='Financial Statements'!D8/'Financial Statements'!D$10 -> 0.73770248 | E8: ='Financial Statements'!E8/'Financial Statements'!E$10 -> 0.75406549 | F8: ='Financial Statements'!F8/'Financial Statements'!F$10 -> 0.7777111
B9: ='Financial Statements'!B9 -> Services | C9: % | D9: ='Financial Statements'!D9/'Financial Statements'!D$10 -> 0.26229752 | E9: ='Financial Statements'!E9/'Financial Statements'!E$10 -> 0.24593451 | F9: ='Financial Statements'!F9/'Financial Statements'!F$10 -> 0.2222889
B10: ='Financial Statements'!B10 -> Total net sales | C10: % | D10: ='Financial Statements'!D10/'Financial Statements'!D$10 -> 1 | E10: ='Financial Statements'!E10/'Financial Statements'!E$10 -> 1 | F10: ='Financial Statements'!F10/'Financial Statements'!F$10 -> 1
B12: ='Financial Statements'!B12 -> Cost of sales:
B13: ='Financial Statements'!B13 -> Products | C13: % | D13: ='Financial Statements'!D13/'Financial Statements'!D$10 -> 0.46644448 | E13: ='Financial Statements'!E13/'Financial Statements'!E$10 -> 0.47369929 | F13: ='Financial Statements'!F13/'Financial Statements'!F$10 -> 0.4938414
B14: ='Financial Statements'!B14 -> Services | C14: % | D14: ='Financial Statements'!D14/'Financial Statements'!D$10 -> 0.064503882 | E14: ='Financial Statements'!E14/'Financial Statements'!E$10 -> 0.064237217 | F14: ='Financial Statements'!F14/'Financial Statements'!F$10 -> 0.064847307
B15: ='Financial Statements'!B15 -> Total cost of sales | C15: % | D15: ='Financial Statements'!D15/'Financial Statements'!D$10 -> 0.53094836 | E15: ='Financial Statements'!E15/'Financial Statements'!E$10 -> 0.5379365 | F15: ='Financial Statements'!F15/'Financial Statements'!F$10 -> 0.5586887
B16: ='Financial Statements'!B16 -> Gross margin | C16: % | D16: ='Financial Statements'!D16/'Financial Statements'!D$10 -> 0.46905164 | E16: ='Financial Statements'!E16/'Financial Statements'!E$10 -> 0.4620635 | F16: ='Financial Statements'!F16/'Financial Statements'!F$10 -> 0.4413113
B18: ='Financial Statements'!B18 -> Operating expenses:
B19: ='Financial Statements'!B19 -> Research and development | C19: % | D19: ='Financial Statements'!D19/'Financial Statements'!D$10 -> 0.083020754 | E19: ='Financial Statements'!E19/'Financial Statements'!E$10 -> 0.080222998 | F19: ='Financial Statements'!F19/'Financial Statements'!F$10 -> 0.078048971
B20: ='Financial Statements'!B20 -> Selling, general and administrative | C20: % | D20: ='Financial Statements'!D20/'Financial Statements'!D$10 -> 0.066322889 | E20: ='Financial Statements'!E20/'Financial Statements'!E$10 -> 0.066738272 | F20: ='Financial Statements'!F20/'Financial Statements'!F$10 -> 0.065048202
B21: ='Financial Statements'!B21 -> Total operating expenses | C21: % | D21: ='Financial Statements'!D21/'Financial Statements'!D$10 -> 0.14934364 | E21: ='Financial Statements'!E21/'Financial Statements'!E$10 -> 0.14696127 | F21: ='Financial Statements'!F21/'Financial Statements'!F$10 -> 0.14309717
B23: ='Financial Statements'!B23 -> Operating income | C23: % | D23: ='Financial Statements'!D23/'Financial Statements'!D$10 -> 0.319708 | E23: ='Financial Statements'!E23/'Financial Statements'!E$10 -> 0.31510223 | F23: ='Financial Statements'!F23/'Financial Statements'!F$10 -> 0.29821412
B24: ='Financial Statements'!B24 -> Other income/(expense), net | C24: % | D24: ='Financial Statements'!D24/'Financial Statements'!D$10 -> -0.00077133609 | E24: ='Financial Statements'!E24/'Financial Statements'!E$10 -> 0.00068791796 | F24: ='Financial Statements'!F24/'Financial Statements'!F$10 -> -0.0014740989
B25: ='Financial Statements'!B25 -> Income before provision for income taxes | C25: % | D25: ='Financial Statements'!D25/'Financial Statements'!D$10 -> 0.31893666 | E25: ='Financial Statements'!E25/'Financial Statements'!E$10 -> 0.31579015 | F25: ='Financial Statements'!F25/'Financial Statements'!F$10 -> 0.29674002
B26: ='Financial Statements'!B26 -> Provision for income taxes | C26: % | D26: ='Financial Statements'!D26/'Financial Statements'!D$10 -> 0.04978602 | E26: ='Financial Statements'!E26/'Financial Statements'!E$10 -> 0.076077589 | F26: ='Financial Statements'!F26/'Financial Statements'!F$10 -> 0.043677681
B27: ='Financial Statements'!B27 -> Net income | C27: % | D27: ='Financial Statements'!D27/'Financial Statements'!D$10 -> 0.26915064 | E27: ='Financial Statements'!E27/'Financial Statements'!E$10 -> 0.23971256 | F27: ='Financial Statements'!F27/'Financial Statements'!F$10 -> 0.25306234
B29: Balance Sheet
B31: =IFERROR('Financial Statements'!B31,"") -> Current assets:
B32: =IFERROR('Financial Statements'!B32,"") -> Cash and cash equivalents | C32: % | D32: =IFERROR('Financial Statements'!D32/'Financial Statements'!D$46, "") -> 0.10002756 | E32: =IFERROR('Financial Statements'!E32/'Financial Statements'!E$46, "") -> 0.082040112
B33: =IFERROR('Financial Statements'!B33,"") -> Marketable securities | C33: % | D33: =IFERROR('Financial Statements'!D33/'Financial Statements'!D$46, "") -> 0.052229562 | E33: =IFERROR('Financial Statements'!E33/'Financial Statements'!E$46, "") -> 0.096520357
B34: =IFERROR('Financial Statements'!B34,"") -> Accounts receivable, net | C34: % | D34: =IFERROR('Financial Statements'!D34/'Financial Statements'!D$46, "") -> 0.11072511 | E34: =IFERROR('Financial Statements'!E34/'Financial Statements'!E$46, "") -> 0.091539262
B35: =IFERROR('Financial Statements'!B35,"") -> Vendor non-trade receivables | C35: % | D35: =IFERROR('Financial Statements'!D35/'Financial Statements'!D$46, "") -> 0.092361395 | E35: =IFERROR('Financial Statements'!E35/'Financial Statements'!E$46, "") -> 0.089958354
B36: =IFERROR('Financial Statements'!B36,"") -> Inventories | C36: % | D36: =IFERROR('Financial Statements'!D36/'Financial Statements'!D$46, "") -> 0.015916891 | E36: =IFERROR('Financial Statements'!E36/'Financial Statements'!E$46, "") -> 0.019962738
B37: =IFERROR('Financial Statements'!B37,"") -> Other current assets | C37: % | D37: =IFERROR('Financial Statements'!D37/'Financial Statements'!D$46, "") -> 0.040599486 | E37: =IFERROR('Financial Statements'!E37/'Financial Statements'!E$46, "") -> 0.039144611
B38: =IFERROR('Financial Statements'!B38,"") -> Total current assets | C38: % | D38: =IFERROR('Financial Statements'!D38/'Financial Statements'!D$46, "") -> 0.41186 | E38: =IFERROR('Financial Statements'!E38/'Financial Statements'!E$46, "") -> 0.41916543
D39: =IFERROR('Financial Statements'!D39/'Financial Statements'!D$46, "") | E39: =IFERROR('Financial Statements'!E39/'Financial Statements'!E$46, "")
B40: =IFERROR('Financial Statements'!B40,"") -> Non-current assets: | D40: =IFERROR('Financial Statements'!D40/'Financial Statements'!D$46, "") | E40: =IFERROR('Financial Statements'!E40/'Financial Statements'!E$46, "")
B41: =IFERROR('Financial Statements'!B41,"") -> Marketable securities | C41: % | D41: =IFERROR('Financial Statements'!D41/'Financial Statements'!D$46, "") -> 0.21635337 | E41: =IFERROR('Financial Statements'!E41/'Financial Statements'!E$46, "") -> 0.25064113
B42: =IFERROR('Financial Statements'!B42,"") -> Property, plant and equipment, net | C42: % | D42: =IFERROR('Financial Statements'!D42/'Financial Statements'!D$46, "") -> 0.13872025 | E42: =IFERROR('Financial Statements'!E42/'Financial Statements'!E$46, "") -> 0.12515754
B43: =IFERROR('Financial Statements'!B43,"") -> Other non-current assets | C43: % | D43: =IFERROR('Financial Statements'!D43/'Financial Statements'!D$46, "") -> 0.23306638 | E43: =IFERROR('Financial Statements'!E43/'Financial Statements'!E$46, "") -> 0.20503589
B44: =IFERROR('Financial Statements'!B44,"") -> Total non-current assets | C44: % | D44: =IFERROR('Financial Statements'!D44/'Financial Statements'!D$46, "") -> 0.58814 | E44: =IFERROR('Financial Statements'!E44/'Financial Statements'!E$46, "") -> 0.58083457
D45: =IFERROR('Financial Statements'!D45/'Financial Statements'!D$46, "") | E45: =IFERROR('Financial Statements'!E45/'Financial Statements'!E$46, "")
B46: =IFERROR('Financial Statements'!B46,"") -> Total assets | C46: % | D46: =IFERROR('Financial Statements'!D46/'Financial Statements'!D$46, "") -> 1 | E46: =IFERROR('Financial Statements'!E46/'Financial Statements'!E$46, "") -> 1
D47: =IFERROR('Financial Statements'!D47/'Financial Statements'!D$46, "") | E47: =IFERROR('Financial Statements'!E47/'Financial Statements'!E$46, "")
B48: =IFERROR('Financial Statements'!B48,"") -> Current liabilities: | D48: =IFERROR('Financial Statements'!D48/'Financial Statements'!D$46, "") | E48: =IFERROR('Financial Statements'!E48/'Financial Statements'!E$46, "")
B49: =IFERROR('Financial Statements'!B49,"") -> Accounts payable | C49: % | D49: =IFERROR('Financial Statements'!D49/'Financial Statements'!D$46, "") -> 0.19446555 | E49: =IFERROR('Financial Statements'!E49/'Financial Statements'!E$46, "") -> 0.18894186
...

Sheet Ratios
B2: Apple Inc. Ratios
C4: Units | D4: ='Financial Statements'!D4 -> 46290 | E4: ='Financial Statements'!E4 -> 46289 | F4: ='Financial Statements'!F4 -> 46288 | G4: Trend
B6: Profitability Ratios
G7: R to L
B8: Gross Margin | C8: % | D8: ='Financial Statements'!D16/'Financial Statements'!D10 -> 0.46905164 | E8: ='Financial Statements'!E16/'Financial Statements'!E10 -> 0.4620635 | F8: ='Financial Statements'!F16/'Financial Statements'!F10 -> 0.4413113
B9: Net Margin | C9: % | D9: ='Financial Statements'!D27/'Financial Statements'!D10 -> 0.26915064 | E9: ='Financial Statements'!E27/'Financial Statements'!E10 -> 0.23971256 | F9: ='Financial Statements'!F27/'Financial Statements'!F10 -> 0.25306234
B10: Operating Cost Margin | C10: % | D10: =SUM('Financial Statements'!D21,'Financial Statements'!D15)/'Financial Statements'!D10 -> 0.680292 | E10: =SUM('Financial Statements'!E21,'Financial Statements'!E15)/'Financial Statements'!E10 -> 0.68489777 | F10: =SUM('Financial Statements'!F21,'Financial Statements'!F15)/'Financial Statements'!F10 -> 0.70178588
B11: Operating Profit Margin | C11: % | D11: =('Financial Statements'!D16-'Financial Statements'!D21+'Financial Statements'!D23-'Financial Statements'!D26)/'Financial Statements'!D10 -> 0.58962997 | E11: =('Financial Statements'!E16-'Financial Statements'!E21+'Financial Statements'!E23-'Financial Statements'!E26)/'Financial Statements'!E10 -> 0.55412687 | F11: =('Financial Statements'!F16-'Financial Statements'!F21+'Financial Statements'!F23-'Financial Statements'!F26)/'Financial Statements'!F10 -> 0.55275056
B12: EPS | D12: 7.46 | E12: 6.08 | F12: 6.13
B13: P/E Ratio
B14: ROCE | C14: % | D14: =IFERROR('Financial Statements'!D25/('Financial Statements'!D46-'Financial Statements'!D54),"") -> 0.68554827 | E14: =IFERROR('Financial Statements'!E25/('Financial Statements'!E46-'Financial Statements'!E54),"") -> 0.65478716
B16: Average NPM | C16: % | D16: =AVERAGE(D9,E9,F9) -> 0.25397518
B18: Liquidity Ratios
B20: Current Ratio | D20: ='Financial Statements'!D38/'Financial Statements'!D54 -> 0.89329292 | E20: ='Financial Statements'!E38/'Financial Statements'!E54 -> 0.86731258
B21: Quick Ratio | D21: =('Financial Statements'!D38-'Financial Statements'!D36)/'Financial Statements'!D54 -> 0.8587704 | E21: =('Financial Statements'!E38-'Financial Statements'!E36)/'Financial Statements'!E54 -> 0.82600685
B23: Solvency Ratios
B25: Debt to Equit Ratio | D25: ='Financial Statements'!D60/'Financial Statements'!E66 -> 5.0133099 | E25: ='Financial Statements'!E60/'Financial Statements'!E66 -> 5.4087796
B26: Proprietery Ratio | D26: ='Financial Statements'!D66/'Financial Statements'!D46 -> 0.20524662 | E26: ='Financial Statements'!E66/'Financial Statements'!E46 -> 0.15603595
B27: Debt to Total Assets | D27: ='Financial Statements'!D59/'Financial Statements'!D46 -> 0.33369521 | E27: ='Financial Statements'!E59/'Financial Statements'!E46 -> 0.36067182
B28: Interest Coverage
B30: Efficiency Ratios/ Activity Ratios
B32: Trade Payables turnover | D32: =('Financial Statements'!D49/'Financial Statements'!D10)*365 -> 61.271719 | E32: =('Financial Statements'!E49/'Financial Statements'!E10)*365 -> 64.368663
B33: Working capital turnover | D33: ='Financial Statements'!D16/Ratios!D35 -> -11.044529 | E33: ='Financial Statements'!E16/Ratios!E35 -> -7.7198462
B35: Working Capital | C35: $ | D35: ='Financial Statements'!D38-'Financial Statements'!D54 -> -17674 | E35: ='Financial Statements'!E38-'Financial Statements'!E54 -> -23405

Sheet Revenue Analysis
B2: Apple Inc. Revenue Analysis
C4: Units | D4: 46290 | E4: 46289 | F4: 46288 | G4: Average
B6: Total Revenue | C6: $ | D6: ='Financial Statements'!D10 -> 416161 | E6: ='Financial Statements'!E10 -> 391035 | F6: ='Financial Statements'!F10 -> 383285 | G6: =AVERAGE(D6,E6,F6) -> 396827
B7: Revenue Growth | C7: % | D7: =('Financial Statements'!D10-'Financial Statements'!E10)/'Financial Statements'!E10 -> 0.064255118 | E7: =('Financial Statements'!E10-'Financial Statements'!F10)/'Financial Statements'!F10 -> 0.020219941 | F7: -0.028 | G7: =AVERAGE(D7,E7,F7) -> 0.01882502
B8: Products Revenue | C8: $ | D8: ='Financial Statements'!D8 -> 307003 | E8: ='Financial Statements'!E8 -> 294866 | F8: ='Financial Statements'!F8 -> 298085 | G8: =AVERAGE(D8,E8,F8) -> 299984.67
B9: Services Revenue | C9: $ | D9: ='Financial Statements'!D9 -> 109158 | E9: ='Financial Statements'!E9 -> 96169 | F9: ='Financial Statements'!F9 -> 85200 | G9: =AVERAGE(D9,E9,F9) -> 96842.333
B10: Products Revenue Growth | C10: % | D10: =(D8-E8)/E8 -> 0.04116107 | E10: =(E8-F8)/F8 -> -0.010798933 | F10: -0.0573 | G10: =AVERAGE(D10,E10,F10) -> -0.0089792878
B11: Services Revenue Growth | C11: % | D11: =(D9-E9)/E9 -> 0.13506431 | E11: =(E9-F9)/F9 -> 0.12874413 | F11: 0.0905 | G11: =AVERAGE(D11,E11,F11) -> 0.11810282
B12: Products as % of revenue | C12: % | D12: ='Common Size Statement'!D8 -> 0.73770248 | E12: ='Common Size Statement'!E8 -> 0.75406549 | F12: ='Common Size Statement'!F8 -> 0.7777111 | G12: =AVERAGE(D12,E12,F12) -> 0.75649302
B13: Services as % of revenue | C13: % | D13: ='Common Size Statement'!D9 -> 0.26229752 | E13: ='Common Size Statement'!E9 -> 0.24593451 | F13: ='Common Size Statement'!F9 -> 0.2222889 | G13: =AVERAGE(D13,E13,F13) -> 0.24350698

Sheet Profitability Analysis
B2: Apple Inc. Profitability Analysis
C4: Units | D4: 46290 | E4: 46289 | F4: 46288 | G4: Average | H4: Trend
B6: Gross margin | C6: % | D6: =Ratios!D8 -> 0.46905164 | E6: =Ratios!E8 -> 0.4620635 | F6: =Ratios!F8 -> 0.4413113 | G6: =AVERAGE(D6,F6,E6) -> 0.45747548
B7: Products Gross Margin | C7: % | D7: 0.368 | E7: 0.372 | F7: 0.365 | G7: =AVERAGE(D7,F7,E7) -> 0.36833333
B8: Services Gross Margin | C8: % | D8: 0.754 | E8: 0.739 | F8: 0.708 | G8: =AVERAGE(D8,F8,E8) -> 0.73366667
B9: Operating Profit Margin | C9: % | D9: =Ratios!D11 -> 0.58962997 | E9: =Ratios!E11 -> 0.55412687 | F9: =Ratios!F11 -> 0.55275056 | G9: =AVERAGE(D9,F9,E9) -> 0.56550247
B10: Net Profit Margin | C10: % | D10: =Ratios!D9 -> 0.26915064 | E10: =Ratios!E9 -> 0.23971256 | F10: =Ratios!F9 -> 0.25306234 | G10: =AVERAGE(D10,F10,E10) -> 0.25397518

Sheet Cashflow Analysis
B2: Apple Inc. Profitability Analysis
C4: Units | D4: 46290 | E4: 46289 | F4: 46288
B6: Operating Cash Flow | C6: $ | D6: ='Financial Statements'!D90 -> 111482 | E6: ='Financial Statements'!E90 -> 118254 | F6: ='Financial Statements'!F90 -> 110543
B7: Capital Expenditure | C7: $ | D7: =ABS('Financial Statements'!D97) -> 12715 | E7: =ABS('Financial Statements'!E97) -> 9447 | F7: =ABS('Financial Statements'!F97) -> 10959
B8: Free Cash Flow | C8: $ | D8: ='Financial Statements'!D116 -> 35934 | E8: ='Financial Statements'!E116 -> 29943 | F8: ='Financial Statements'!F116 -> 30737
B9: Share Repurchase | C9: $ | D9: =ABS('Financial Statements'!D106) -> 90711 | E9: =ABS('Financial Statements'!E106) -> 94949 | F9: =ABS('Financial Statements'!F106) -> 77550
B10: Dividends or dividend equivalents | C10: $ | D10: =ABS('Financial Statements'!D105) -> 15421 | E10: =ABS('Financial Statements'!E105) -> 15234 | F10: =ABS('Financial Statements'!F105) -> 15025
B12: % of Operating Cash Flow | C12: % | D12: =IFERROR(D6/D$6, "") -> 1 | E12: =IFERROR(E6/E$6, "") -> 1 | F12: =IFERROR(F6/F$6, "") -> 1
B13: =B7 -> Capital Expenditure | C13: % | D13: =IFERROR(D7/D$6, "") -> 0.11405429 | E13: =IFERROR(E7/E$6, "") -> 0.079887361 | F13: =IFERROR(F7/F$6, "") -> 0.099137892
B14: =B8 -> Free Cash Flow | C14: % | D14: =IFERROR(D8/D$6, "") -> 0.32233006 | E14: =IFERROR(E8/E$6, "") -> 0.25320919 | F14: =IFERROR(F8/F$6, "") -> 0.27805469
B15: =B9 -> Share Repurchase | C15: % | D15: =IFERROR(D9/D$6, "") -> 0.81368293 | E15: =IFERROR(E9/E$6, "") -> 0.80292421 | F15: =IFERROR(F9/F$6, "") -> 0.70153696
B16: =B10 -> Dividends or dividend equivalents | C16: % | D16: =IFERROR(D10/D$6, "") -> 0.13832726 | E16: =IFERROR(E10/E$6, "") -> 0.12882439 | F16: =IFERROR(F10/F$6, "") -> 0.13591996

Sheet Key Metrics
B2: Apple Inc. Key Metrics
C4: Units | D4: 46290 | E4: 46289 | F4: 46288
B6: ROE | C6: % | D6: ='Financial Statements'!D27/AVERAGE('Financial Statements'!D66,'Financial Statements'!E66) -> 1.7142245
B7: ROCE | C7: % | D7: =Ratios!D14 -> 0.68554827 | E7: =Ratios!E14 -> 0.65478716
B8: Net Margin | C8: % | D8: =Ratios!D9 -> 0.26915064 | E8: =Ratios!E9 -> 0.23971256 | F8: =Ratios!F9 -> 0.25306234
B9: Asset Turnover | D9: ='Financial Statements'!D10/AVERAGE('Financial Statements'!E42,'Financial Statements'!D42) -> 8.7141361
B10: Debt/Equity ratio | D10: =Ratios!D25 -> 5.0133099 | E10: =Ratios!E25 -> 5.4087796
B11: P/E ratio | D11: 34.04 | E11: 38.04 | F11: 27.58

Sheet Historical Analysis
B2: Fiscal Year 2023-2025
B4: Metric | C4: Observation | D4: Interpretation
B6: Revenue | C6: The average revenue growth each year since 2023 is 1.88%. Revenue grew 5.65% from 2023 to 2025. Average product growth was (0.90%), however it still remained 75.65% of revenue. Services grew by 11.81%, and averaged 24.35% of revenue. | D6: The growth driver remains services, but products accounts as revenue generators. Apple's growth is becoming less dependent on sale of hardware, although it still relies on it for cash inflow.
B7: Profitability | C7: The average gross margin from 2023 is 45.75%. There's been a decline in the products gross margin, and an increase in services gross margin. NPM has seen a steady rise. | D7: The profit driver remains services, grossing 73.37% in 3 years. The decline was driven by decrease in the sales of wearable and accessories, signifying that Apple's entire product segment isn't weak. Management did not provide any specific reason, suggesting it was either not considered a material strategic issue or it was outweighed by stronger performance in other areas, particularly services.
B8: Balance Sheet | C8: There is a decrease in marketable securities, short and long term, and a decrease in the closing balance of inventory. This offsets the increase in PPE, and other assets in the total. Apple has reduced it's term debt, accumulated deficit, and comprehensive losses, while increasing it's common stock. From a broader lense, the debt % has reduced and the equity % has increased. | D8: The company is trying to reduce leverage and increase equity. Reductions in marketable securities are due to reductions in Non-US securities and corporate debt bonds, which could mean company is trying to reduce risk. But that doesn't add up because company increased investment in money market funds. Apple also chose to not disclose any sale or purchase of inventory under accounting regulations, which now does not allow a clear picture of whether the decrease in inventory is due to higher sales, or reduced production.
B9: Cash Flow | C9: The cashflow from operating activities has declined compared to the previous year, but this is the segment that generates the maximum cash. Apple uses a lot of cash in financing activities, mainly on repurchase of stock which was 81.37% of its operating cash flow. The comapny also significantly increased cashflow from investing activites, which was mostly a factor of the proceeds from marketable securities and reduced purchase of marketable securities | D9: Apple records a steady expenditure of stock repurchase over the years. The significant increase in investing activities could be an indication that the company is trying to be more liquid. Proceeds from sale is key cashflow generator.
B10: Capital Allocation | C10: Over the 3 years, Apple's dividends have been stable. However, every year the company buys back a large sum of it's shares. In 2025 it utilised 81.37% of it's operating cash flow to repurchase its stock. Apple also spends a consistent 8% of its revenue on R&D. The company averages 9.77% capital expenditure of its operating cash. | D10: The company's priority is evidently giving back to it's shareholders and increasing the current value of their shares. It also has a commitment to R&D, focusing on innovation to compete in the industry.
B11: Efficiency | C11: Apple's ROE is 171.42% and the asset turnover ratio is 8.71 times. Although, the working capital turnover ratio is -11.04x in 2025. This is because of the negative working capital. | D11: Apple seems highly efficient generating return on equity, however this number fails to represent that Apple has a high leverage.
